const x = 10

// continua o código
try {
    x = 2
} catch(err) {
    console.log(`Erro: ${err}`)
}

console.log('Continuando o código')